[2025-07-08T16:39:57.115+0000] {local_task_job_runner.py:123} INFO - ::group::Pre task execution logs
[2025-07-08T16:39:57.145+0000] {taskinstance.py:2631} INFO - Dependencies all met for dep_context=non-requeueable deps ti=<TaskInstance: process_exercises.identify_ready_exercises manual__2025-07-08T16:39:55.379473+00:00 [queued]>
[2025-07-08T16:39:57.154+0000] {taskinstance.py:2631} INFO - Dependencies all met for dep_context=requeueable deps ti=<TaskInstance: process_exercises.identify_ready_exercises manual__2025-07-08T16:39:55.379473+00:00 [queued]>
[2025-07-08T16:39:57.155+0000] {taskinstance.py:2884} INFO - Starting attempt 1 of 1
[2025-07-08T16:39:57.204+0000] {taskinstance.py:2907} INFO - Executing <Task(PythonOperator): identify_ready_exercises> on 2025-07-08 16:39:55.379473+00:00
[2025-07-08T16:39:57.212+0000] {logging_mixin.py:190} WARNING - /home/airflow/.local/lib/python3.12/site-packages/airflow/task/task_runner/standard_task_runner.py:70 DeprecationWarning: This process (pid=7059) is multi-threaded, use of fork() may lead to deadlocks in the child.
[2025-07-08T16:39:57.213+0000] {standard_task_runner.py:72} INFO - Started process 7060 to run task
[2025-07-08T16:39:57.212+0000] {standard_task_runner.py:104} INFO - Running: ['airflow', 'tasks', 'run', 'process_exercises', 'identify_ready_exercises', 'manual__2025-07-08T16:39:55.379473+00:00', '--job-id', '159', '--raw', '--subdir', 'DAGS_FOLDER/process_exercises.py', '--cfg-path', '/tmp/tmpm0pstf_x']
[2025-07-08T16:39:57.214+0000] {standard_task_runner.py:105} INFO - Job 159: Subtask identify_ready_exercises
[2025-07-08T16:39:57.342+0000] {task_command.py:467} INFO - Running <TaskInstance: process_exercises.identify_ready_exercises manual__2025-07-08T16:39:55.379473+00:00 [running]> on host 3748f1b8240a
[2025-07-08T16:39:57.579+0000] {taskinstance.py:3157} INFO - Exporting env vars: AIRFLOW_CTX_DAG_OWNER='airflow' AIRFLOW_CTX_DAG_ID='process_exercises' AIRFLOW_CTX_TASK_ID='identify_ready_exercises' AIRFLOW_CTX_EXECUTION_DATE='2025-07-08T16:39:55.379473+00:00' AIRFLOW_CTX_TRY_NUMBER='1' AIRFLOW_CTX_DAG_RUN_ID='manual__2025-07-08T16:39:55.379473+00:00'
[2025-07-08T16:39:57.581+0000] {taskinstance.py:740} INFO - ::endgroup::
[2025-07-08T16:39:57.649+0000] {base.py:84} INFO - Retrieving connection 'minio-ebsim'
[2025-07-08T16:39:57.651+0000] {connection_wrapper.py:328} INFO - AWS Connection (conn_id='minio-ebsim', conn_type='aws') credentials retrieved from extra.
[2025-07-08T16:39:58.028+0000] {logging_mixin.py:190} INFO - ‚ùå [DAG] erro ao carregar manifest: üõë [DAG] Nenhum exerc√≠cio pronto para processamento. Encerrando DAG.
[2025-07-08T16:39:58.029+0000] {taskinstance.py:3336} ERROR - Task failed with exception
Traceback (most recent call last):
  File "/home/airflow/.local/lib/python3.12/site-packages/airflow/models/taskinstance.py", line 776, in _execute_task
    result = _execute_callable(context=context, **execute_callable_kwargs)
             ^^^^^^^^^^^^^^^^^^^^^^^^^^^^^^^^^^^^^^^^^^^^^^^^^^^^^^^^^^^^^
  File "/home/airflow/.local/lib/python3.12/site-packages/airflow/models/taskinstance.py", line 742, in _execute_callable
    return ExecutionCallableRunner(
           ^^^^^^^^^^^^^^^^^^^^^^^^
  File "/home/airflow/.local/lib/python3.12/site-packages/airflow/utils/operator_helpers.py", line 252, in run
    return self.func(*args, **kwargs)
           ^^^^^^^^^^^^^^^^^^^^^^^^^^
  File "/home/airflow/.local/lib/python3.12/site-packages/airflow/models/baseoperator.py", line 424, in wrapper
    return func(self, *args, **kwargs)
           ^^^^^^^^^^^^^^^^^^^^^^^^^^^
  File "/home/airflow/.local/lib/python3.12/site-packages/airflow/operators/python.py", line 238, in execute
    return_value = self.execute_callable()
                   ^^^^^^^^^^^^^^^^^^^^^^^
  File "/home/airflow/.local/lib/python3.12/site-packages/airflow/operators/python.py", line 256, in execute_callable
    return runner.run(*self.op_args, **self.op_kwargs)
           ^^^^^^^^^^^^^^^^^^^^^^^^^^^^^^^^^^^^^^^^^^^
  File "/home/airflow/.local/lib/python3.12/site-packages/airflow/utils/operator_helpers.py", line 252, in run
    return self.func(*args, **kwargs)
           ^^^^^^^^^^^^^^^^^^^^^^^^^^
  File "/opt/airflow/dags/process_exercises.py", line 76, in identify_ready_exercises
    raise ValueError("üõë [DAG] Nenhum exerc√≠cio pronto para processamento. Encerrando DAG.")
ValueError: üõë [DAG] Nenhum exerc√≠cio pronto para processamento. Encerrando DAG.
[2025-07-08T16:39:58.058+0000] {taskinstance.py:1242} INFO - Marking task as FAILED. dag_id=process_exercises, task_id=identify_ready_exercises, run_id=manual__2025-07-08T16:39:55.379473+00:00, execution_date=20250708T163955, start_date=20250708T163957, end_date=20250708T163958
[2025-07-08T16:39:58.179+0000] {taskinstance.py:349} INFO - ::group::Post task execution logs
[2025-07-08T16:39:58.180+0000] {standard_task_runner.py:124} ERROR - Failed to execute job 159 for task identify_ready_exercises (üõë [DAG] Nenhum exerc√≠cio pronto para processamento. Encerrando DAG.; 7060)
Traceback (most recent call last):
  File "/home/airflow/.local/lib/python3.12/site-packages/airflow/task/task_runner/standard_task_runner.py", line 117, in _start_by_fork
    ret = args.func(args, dag=self.dag)
          ^^^^^^^^^^^^^^^^^^^^^^^^^^^^^
  File "/home/airflow/.local/lib/python3.12/site-packages/airflow/cli/cli_config.py", line 49, in command
    return func(*args, **kwargs)
           ^^^^^^^^^^^^^^^^^^^^^
  File "/home/airflow/.local/lib/python3.12/site-packages/airflow/utils/cli.py", line 116, in wrapper
    return f(*args, **kwargs)
           ^^^^^^^^^^^^^^^^^^
  File "/home/airflow/.local/lib/python3.12/site-packages/airflow/cli/commands/task_command.py", line 483, in task_run
    task_return_code = _run_task_by_selected_method(args, _dag, ti)
                       ^^^^^^^^^^^^^^^^^^^^^^^^^^^^^^^^^^^^^^^^^^^^
  File "/home/airflow/.local/lib/python3.12/site-packages/airflow/cli/commands/task_command.py", line 256, in _run_task_by_selected_method
    return _run_raw_task(args, ti)
           ^^^^^^^^^^^^^^^^^^^^^^^
  File "/home/airflow/.local/lib/python3.12/site-packages/airflow/cli/commands/task_command.py", line 341, in _run_raw_task
    return ti._run_raw_task(
           ^^^^^^^^^^^^^^^^^
  File "/home/airflow/.local/lib/python3.12/site-packages/airflow/utils/session.py", line 97, in wrapper
    return func(*args, session=session, **kwargs)
           ^^^^^^^^^^^^^^^^^^^^^^^^^^^^^^^^^^^^^^
  File "/home/airflow/.local/lib/python3.12/site-packages/airflow/models/taskinstance.py", line 3029, in _run_raw_task
    return _run_raw_task(
           ^^^^^^^^^^^^^^
  File "/home/airflow/.local/lib/python3.12/site-packages/airflow/models/taskinstance.py", line 282, in _run_raw_task
    TaskInstance._execute_task_with_callbacks(
  File "/home/airflow/.local/lib/python3.12/site-packages/airflow/models/taskinstance.py", line 3184, in _execute_task_with_callbacks
    result = self._execute_task(context, task_orig)
             ^^^^^^^^^^^^^^^^^^^^^^^^^^^^^^^^^^^^^^
  File "/home/airflow/.local/lib/python3.12/site-packages/airflow/models/taskinstance.py", line 3208, in _execute_task
    return _execute_task(self, context, task_orig)
           ^^^^^^^^^^^^^^^^^^^^^^^^^^^^^^^^^^^^^^^
  File "/home/airflow/.local/lib/python3.12/site-packages/airflow/models/taskinstance.py", line 776, in _execute_task
    result = _execute_callable(context=context, **execute_callable_kwargs)
             ^^^^^^^^^^^^^^^^^^^^^^^^^^^^^^^^^^^^^^^^^^^^^^^^^^^^^^^^^^^^^
  File "/home/airflow/.local/lib/python3.12/site-packages/airflow/models/taskinstance.py", line 742, in _execute_callable
    return ExecutionCallableRunner(
           ^^^^^^^^^^^^^^^^^^^^^^^^
  File "/home/airflow/.local/lib/python3.12/site-packages/airflow/utils/operator_helpers.py", line 252, in run
    return self.func(*args, **kwargs)
           ^^^^^^^^^^^^^^^^^^^^^^^^^^
  File "/home/airflow/.local/lib/python3.12/site-packages/airflow/models/baseoperator.py", line 424, in wrapper
    return func(self, *args, **kwargs)
           ^^^^^^^^^^^^^^^^^^^^^^^^^^^
  File "/home/airflow/.local/lib/python3.12/site-packages/airflow/operators/python.py", line 238, in execute
    return_value = self.execute_callable()
                   ^^^^^^^^^^^^^^^^^^^^^^^
  File "/home/airflow/.local/lib/python3.12/site-packages/airflow/operators/python.py", line 256, in execute_callable
    return runner.run(*self.op_args, **self.op_kwargs)
           ^^^^^^^^^^^^^^^^^^^^^^^^^^^^^^^^^^^^^^^^^^^
  File "/home/airflow/.local/lib/python3.12/site-packages/airflow/utils/operator_helpers.py", line 252, in run
    return self.func(*args, **kwargs)
           ^^^^^^^^^^^^^^^^^^^^^^^^^^
  File "/opt/airflow/dags/process_exercises.py", line 76, in identify_ready_exercises
    raise ValueError("üõë [DAG] Nenhum exerc√≠cio pronto para processamento. Encerrando DAG.")
ValueError: üõë [DAG] Nenhum exerc√≠cio pronto para processamento. Encerrando DAG.
[2025-07-08T16:39:58.235+0000] {local_task_job_runner.py:266} INFO - Task exited with return code 1
[2025-07-08T16:39:58.270+0000] {taskinstance.py:3924} INFO - 0 downstream tasks scheduled from follow-on schedule check
[2025-07-08T16:39:58.312+0000] {local_task_job_runner.py:245} INFO - ::endgroup::
